[2023-03-03 09:22:16,072] [homeApp.py:52] [homeApp:get_text] [ERROR]- HTTPConnectionPool(host='10.22.573.6', port=8080): Max retries exceeded with url: /generate_bySentence?inputContent1=%E5%A4%A7%E6%95%B0%E6%8D%AE&inputContent2=&k=1 (Caused by NewConnectionError('<urllib3.connection.HTTPConnection object at 0x000001DDF6671208>: Failed to establish a new connection: [Errno 11001] getaddrinfo failed'))
[2023-03-03 09:26:17,087] [homeApp.py:52] [homeApp:get_text] [ERROR]- HTTPConnectionPool(host='10.22.5700.6', port=8080): Max retries exceeded with url: /generate_bySentence?inputContent1=%E4%BD%A0%E8%A7%89%E5%BE%97%E5%91%A2&inputContent2=&k=1 (Caused by NewConnectionError('<urllib3.connection.HTTPConnection object at 0x0000023D252F1B88>: Failed to establish a new connection: [Errno 11001] getaddrinfo failed'))
[2023-03-03 09:26:18,902] [homeApp.py:52] [homeApp:get_text] [ERROR]- HTTPConnectionPool(host='10.22.5700.6', port=8080): Max retries exceeded with url: /generate_bySentence?inputContent1=%E4%BD%A0%E8%A7%89%E5%BE%97%E5%91%A2&inputContent2=%E5%A5%BD%E5%83%8F%E5%87%BA%E9%97%AE%E9%A2%98%E4%BA%86%EF%BC%8C%E8%AF%B7%E5%86%8D%E8%AF%95%E4%B8%80%E6%AC%A1%E6%88%96%E8%81%94%E7%B3%BB%E7%AE%A1%E7%90%86%E5%91%98%EF%BC%9Abryanwang0702@163.com&k=1 (Caused by NewConnectionError('<urllib3.connection.HTTPConnection object at 0x0000023D2534B888>: Failed to establish a new connection: [Errno 11001] getaddrinfo failed'))
[2023-03-03 09:26:20,310] [homeApp.py:52] [homeApp:get_text] [ERROR]- HTTPConnectionPool(host='10.22.5700.6', port=8080): Max retries exceeded with url: /generate_bySentence?inputContent1=%E4%BD%A0%E8%A7%89%E5%BE%97%E5%91%A2&inputContent2=%E5%A5%BD%E5%83%8F%E5%87%BA%E9%97%AE%E9%A2%98%E4%BA%86%EF%BC%8C%E8%AF%B7%E5%86%8D%E8%AF%95%E4%B8%80%E6%AC%A1%E6%88%96%E8%81%94%E7%B3%BB%E7%AE%A1%E7%90%86%E5%91%98%EF%BC%9Abryanwang0702@163.com&k=1 (Caused by NewConnectionError('<urllib3.connection.HTTPConnection object at 0x0000023D2538B9C8>: Failed to establish a new connection: [Errno 11001] getaddrinfo failed'))
